Workbook

Sheet GST Self Invoice
A1: Sl no | B1: Company Name | C1: CIN | D1: Company Address | E1: Company GST Number | F1: Inv date | G1: Inv no | H1: Party Name | I1: City name | J1: Type of Service | K1: SAC CODE | L1: Party state | M1: CGST % | N1: SGST % | O1: IGST % | P1: Taxable value | Q1: IGST | R1: CGST | S1: SGST | T1: Total RCM payable | U1: Round taxable | V1: Round IGST | W1: ROUND CGST | X1: ROUND SGST | Y1: ROUNF TOTAL RCM | Z1: Haryana | AA1: Round total amount | AB1: Amount in Rupees | AC1: Taxable Amount in text | AD1: IGST Amount in text | AE1: CGST Amount in text | AF1: SGST Amount in text | AG1: Total RCM Amount Amount in text | AH1: TOTAL NET AMOUNT
A2: 1 | B2: Hexa Climate Solutions Private Limited | C2: U35105DL2023PTC418669 | D2: Floor 14, Tower B, Vatika Business Park, Sector 49, Sohna Road, Gurgaon-122018 | E2: 06AAGCH9318D1ZO | F2: 45351 | G2: RCM/23-24/11/01 | H2: Anand Kumar Singh | I2: H-3, Second Floor, Jungpura Extension, Delhi - 110014 | J2: Legal fees | K2: =IF(ISBLANK(J2),0,VLOOKUP(J2,Sheet2!$U$7:$V$14,2,0)) -> 998211 | L2: Delhi | M2: 0.09 | N2: =M2 -> 0.09 | O2: 0.18 | P2: 15000 | Q2: =IF($Z$1=L2,0,P2*O2) -> 2700 | R2: =IF($Z$1=L2,P2*M2,0) -> 0 | S2: =IF($Z$1=L2,P2*M2,0) -> 0 | T2: =SUM(Q2:S2) -> 2700 | U2: =ROUND(P2,2) -> 15000 | V2: =ROUND(Q2,2) -> 2700 | W2: =ROUND(R2,2) -> 0 | X2: =ROUND(S2,2) -> 0 | Y2: =ROUND(T2,2) -> 2700 | AA2: =SUBTOTAL(9,U2:X2) -> 17700 | AB2: Seventeen Thousand Seven Hundred Only | AC2: =TEXT(U2,"#,##,###") -> 15,000 | AD2: =TEXT(V2,"#,##,###") -> 2,700 | AE2: =TEXT(W2,"#,##,###") | AF2: =TEXT(X2,"#,##,###") | AG2: =TEXT(Y2,"#,##,###") -> 2,700 | AH2: =TEXT(AA2,"#,##,###") -> 17,700
A3: =A2+1 -> 2 | B3: Hexa Climate Solutions Private Limited | C3: U35105DL2023PTC418669 | D3: Floor 14, Tower B, Vatika Business Park, Sector 49, Sohna Road, Gurgaon-122018 | E3: 06AAGCH9318D1ZO | F3: 45357 | G3: RCM/23-24/12/01 | H3: PVsyst SA | I3: Route de la Maison-Carrée 30, 1242 Satigny, Switzerland | J3: Software Services | K3: =IF(ISBLANK(J3),0,VLOOKUP(J3,Sheet2!$U$7:$V$14,2,0)) -> 997331 | L3: State outside India | M3: 0.09 | N3: =M3 -> 0.09 | O3: 0.18 | P3: 57163.98 | Q3: =IF($Z$1=L3,0,P3*O3) -> 10289.516 | R3: =IF($Z$1=L3,P3*M3,0) -> 0 | S3: =IF($Z$1=L3,P3*M3,0) -> 0 | T3: =SUM(Q3:S3) -> 10289.516 | U3: =ROUND(P3,2) -> 57163.98 | V3: =ROUND(Q3,2) -> 10289.52 | W3: =ROUND(R3,2) -> 0 | X3: =ROUND(S3,2) -> 0 | Y3: =ROUND(T3,2) -> 10289.52 | AA3: =SUBTOTAL(9,U3:X3) -> 67453.5 | AB3: Sixty Seven Thousand Four Hundred Fifty Four Only | AC3: =TEXT(U3,"#,##,###") -> 57,164 | AD3: =TEXT(V3,"#,##,###") -> 10,290 | AE3: =TEXT(W3,"#,##,###") | AF3: =TEXT(X3,"#,##,###") | AG3: =TEXT(Y3,"#,##,###") -> 10,290 | AH3: =TEXT(AA3,"#,##,###") -> 67,454
A4: =A3+1 -> 3 | B4: Hexa Climate Solutions Private Limited | C4: U35105DL2023PTC418669 | D4: Floor 14, Tower B, Vatika Business Park, Sector 49, Sohna Road, Gurgaon-122018 | E4: 06AAGCH9318D1ZO | F4: 45357 | G4: RCM/23-24/12/02 | H4: Solargis S.R.O. | I4: Skypark Offices, Bottova 2A, Stare mesto, Bratislava I., Bratislava, Bratislavsky kraj, Slovakia - 81109 | J4: Software Services | K4: =IF(ISBLANK(J4),0,VLOOKUP(J4,Sheet2!$U$7:$V$14,2,0)) -> 997331 | L4: State outside India | M4: 0.09 | N4: =M4 -> 0.09 | O4: 0.18 | P4: 439764.48 | Q4: =IF($Z$1=L4,0,P4*O4) -> 79157.606 | R4: =IF($Z$1=L4,P4*M4,0) -> 0 | S4: =IF($Z$1=L4,P4*M4,0) -> 0 | T4: =SUM(Q4:S4) -> 79157.606 | U4: =ROUND(P4,2) -> 439764.48 | V4: =ROUND(Q4,2) -> 79157.61 | W4: =ROUND(R4,2) -> 0 | X4: =ROUND(S4,2) -> 0 | Y4: =ROUND(T4,2) -> 79157.61 | AA4: =SUBTOTAL(9,U4:X4) -> 518922.09 | AB4: Five Lacs Eighteen Thousand Nine Hundred Twenty Two Only | AC4: =TEXT(U4,"#,##,###") -> 439,764 | AD4: =TEXT(V4,"#,##,###") -> 79,158 | AE4: =TEXT(W4,"#,##,###") | AF4: =TEXT(X4,"#,##,###") | AG4: =TEXT(Y4,"#,##,###") -> 79,158 | AH4: =TEXT(AA4,"#,##,###") -> 518,922
A5: =A4+1 -> 4 | B5: Hexa Climate Solutions Private Limited | C5: U35105DL2023PTC418669 | D5: Floor 14, Tower B, Vatika Business Park, Sector 49, Sohna Road, Gurgaon-122018 | E5: 06AAGCH9318D1ZO | F5: 45379 | G5: RCM/23-24/12/03 | H5: EMD International A/S | I5: Niels Jernes Vej 10, 9200, Aalborg, Denmark | J5: Software Services | K5: =IF(ISBLANK(J5),0,VLOOKUP(J5,Sheet2!$U$7:$V$14,2,0)) -> 997331 | L5: State outside India | M5: 0.09 | N5: =M5 -> 0.09 | O5: 0.18 | P5: 640795.67 | Q5: =IF($Z$1=L5,0,P5*O5) -> 115343.22 | R5: =IF($Z$1=L5,P5*M5,0) -> 0 | S5: =IF($Z$1=L5,P5*M5,0) -> 0 | T5: =SUM(Q5:S5) -> 115343.22 | U5: =ROUND(P5,2) -> 640795.67 | V5: =ROUND(Q5,2) -> 115343.22 | W5: =ROUND(R5,2) -> 0 | X5: =ROUND(S5,2) -> 0 | Y5: =ROUND(T5,2) -> 115343.22 | AA5: =SUBTOTAL(9,U5:X5) -> 756138.89 | AB5: Seven Lacs Fifty Six Thousand One Hundred Thirty Nine Only | AC5: =TEXT(U5,"#,##,###") -> 640,796 | AD5: =TEXT(V5,"#,##,###") -> 115,343 | AE5: =TEXT(W5,"#,##,###") | AF5: =TEXT(X5,"#,##,###") | AG5: =TEXT(Y5,"#,##,###") -> 115,343 | AH5: =TEXT(AA5,"#,##,###") -> 756,139
A6: =A5+1 -> 5 | B6: Hexa Climate Solutions Private Limited | C6: U35105DL2023PTC418669 | D6: Floor 14, Tower B, Vatika Business Park, Sector 49, Sohna Road, Gurgaon-122018 | E6: 06AAGCH9318D1ZO | F6: 45429 | G6: RCM/24-25/02/01 | H6: Hexa Renewables India Investment PTE LTD | I6: 65, CHULIA STREET, #21-06/07, OCBC CENTRE, SINGAPORE-49513 | J6: Corporate Guarantee Fees | K6: =IF(ISBLANK(J6),0,VLOOKUP(J6,Sheet2!$U$7:$V$14,2,0)) -> 999799 | L6: State outside India | M6: 0.09 | N6: =M6 -> 0.09 | O6: 0.18 | P6: 5581770 | Q6: =IF($Z$1=L6,0,P6*O6) -> 1004718.6 | R6: =IF($Z$1=L6,P6*M6,0) -> 0 | S6: =IF($Z$1=L6,P6*M6,0) -> 0 | T6: =SUM(Q6:S6) -> 1004718.6 | U6: =ROUND(P6,2) -> 5581770 | V6: =ROUND(Q6,2) -> 1004718.6 | W6: =ROUND(R6,2) -> 0 | X6: =ROUND(S6,2) -> 0 | Y6: =ROUND(T6,2) -> 1004718.6 | AA6: =SUBTOTAL(9,U6:X6) -> 6586488.6 | AB6: Sixty Five Lacs Eighty Six Thousand Four Hundred Eighty Nine Only | AC6: =TEXT(U6,"#,##,###") -> 5,581,770 | AD6: =TEXT(V6,"#,##,###") -> 1,004,719 | AE6: =TEXT(W6,"#,##,###") | AF6: =TEXT(X6,"#,##,###") | AG6: =TEXT(Y6,"#,##,###") -> 1,004,719 | AH6: =TEXT(AA6,"#,##,###") -> 6,586,489
A7: =A6+1 -> 6 | B7: Hexa Climate Solutions Private Limited | C7: U35105DL2023PTC418669 | D7: Floor 14, Tower B, Vatika Business Park, Sector 49, Sohna Road, Gurgaon-122018 | E7: 06AAGCH9318D1ZO | F7: 45504 | G7: RCM/24-25/04/01 | H7: Energy Exemplar Pty Ltd | I7: 17 Bagot Street, North Adelaide, South Australia - 5006 | J7: Software Services | K7: =IF(ISBLANK(J7),0,VLOOKUP(J7,Sheet2!$U$7:$V$14,2,0)) -> 997331 | L7: State outside India | M7: 0.09 | N7: =M7 -> 0.09 | O7: 0.18 | P7: 5095200 | Q7: =IF($Z$1=L7,0,P7*O7) -> 917136 | R7: =IF($Z$1=L7,P7*M7,0) -> 0 | S7: =IF($Z$1=L7,P7*M7,0) -> 0 | T7: =SUM(Q7:S7) -> 917136 | U7: =ROUND(P7,2) -> 5095200 | V7: =ROUND(Q7,2) -> 917136 | W7: =ROUND(R7,2) -> 0 | X7: =ROUND(S7,2) -> 0 | Y7: =ROUND(T7,2) -> 917136 | AA7: =SUBTOTAL(9,U7:X7) -> 6012336 | AB7: Sixty Lacs Twelve Thousand Three Hundred Thirty Six Only | AC7: =TEXT(U7,"#,##,###") -> 5,095,200 | AD7: =TEXT(V7,"#,##,###") -> 917,136 | AE7: =TEXT(W7,"#,##,###") | AF7: =TEXT(X7,"#,##,###") | AG7: =TEXT(Y7,"#,##,###") -> 917,136 | AH7: =TEXT(AA7,"#,##,###") -> 6,012,336
A8: =A7+1 -> 7 | B8: Hexa Climate Solutions Private Limited | C8: U35105DL2023PTC418669 | D8: Floor 14, Tower B, Vatika Business Park, Sector 49, Sohna Road, Gurgaon-122018 | E8: 06AAGCH9318D1ZO | F8: 45558 | G8: RCM/24-25/06/01 | H8: UL Services Group LLC | I8: 23 British American Blvd. Latham, NY 12110 United States | J8: Software Services | K8: =IF(ISBLANK(J8),0,VLOOKUP(J8,Sheet2!$U$7:$V$14,2,0)) -> 997331 | L8: State outside India | M8: 0.09 | N8: =M8 -> 0.09 | O8: 0.18 | P8: 302222.88 | Q8: =IF($Z$1=L8,0,P8*O8) -> 54400.118 | R8: =IF($Z$1=L8,P8*M8,0) -> 0 | S8: =IF($Z$1=L8,P8*M8,0) -> 0 | T8: =SUM(Q8:S8) -> 54400.118 | U8: =ROUND(P8,2) -> 302222.88 | V8: =ROUND(Q8,2) -> 54400.12 | W8: =ROUND(R8,2) -> 0 | X8: =ROUND(S8,2) -> 0 | Y8: =ROUND(T8,2) -> 54400.12 | AA8: =SUBTOTAL(9,U8:X8) -> 356623 | AB8: Three Lacs Fifty Six Thousand Six Hundred Twenty Three Only | AC8: =TEXT(U8,"#,##,###") -> 302,223 | AD8: =TEXT(V8,"#,##,###") -> 54,400 | AE8: =TEXT(W8,"#,##,###") | AF8: =TEXT(X8,"#,##,###") | AG8: =TEXT(Y8,"#,##,###") -> 54,400 | AH8: =TEXT(AA8,"#,##,###") -> 356,623
A9: =A8+1 -> 8 | B9: Hea Renewable Solutions Private Limited | C9: U35105DL2024PTC430335 | D9: Floor 14, Tower B, Vatika Business Park, Sector 49, Sohna Road, Gurgaon-122018 | E9: 06AAHCH3225L1ZK | F9: 45492 | G9: RCM/24-25/04/01 | H9: Mohit Gupta Advocate | I9: Dojhana (3-N), Jhajjar, Haryana - 124102 | J9: Legal fees | K9: =IF(ISBLANK(J9),0,VLOOKUP(J9,Sheet2!$U$7:$V$14,2,0)) -> 998211 | L9: Haryana | M9: 0.09 | N9: =M9 -> 0.09 | O9: 0.18 | P9: 70125 | Q9: =IF($Z$1=L9,0,P9*O9) -> 0 | R9: =IF($Z$1=L9,P9*M9,0) -> 6311.25 | S9: =IF($Z$1=L9,P9*M9,0) -> 6311.25 | T9: =SUM(Q9:S9) -> 12622.5 | U9: =ROUND(P9,2) -> 70125 | V9: =ROUND(Q9,2) -> 0 | W9: =ROUND(R9,2) -> 6311.25 | X9: =ROUND(S9,2) -> 6311.25 | Y9: =ROUND(T9,2) -> 12622.5 | AA9: =SUBTOTAL(9,U9:X9) -> 82747.5 | AB9: Eighty Two Thousand Seven Hundred Forty Eight Only | AC9: =TEXT(U9,"#,##,###") -> 70,125 | AD9: =TEXT(V9,"#,##,###") | AE9: =TEXT(W9,"#,##,###") -> 6,311 | AF9: =TEXT(X9,"#,##,###") -> 6,311 | AG9: =TEXT(Y9,"#,##,###") -> 12,623 | AH9: =TEXT(AA9,"#,##,###") -> 82,748

Sheet GST RCM
L1: =SUM(L3:L31) -> 17449726 | M1: =SUM(M3:M31) -> 2866255.6 | N1: =SUM(N3:N31) -> 133710.22 | O1: =SUM(O3:O31) -> 133710.22 | P1: =SUM(P3:P31) -> 3133676
A2: Sl no | B2: Company Name | C2: Inv date | D2: Inv no | E2: Party Name | F2: Type of Service | G2: SAC CODE | H2: Party state | I2: CGST % | J2: SGST % | K2: IGST % | L2: Taxable value | M2: IGST | N2: CGST | O2: SGST | P2: Total RCM payable | Q2: Round taxable | R2: Round IGST | S2: ROUND CGST | T2: ROUND SGST | U2: ROUNF TOTAL RCM | V2: Haryana | W2: Round total amount | X2: Amount in Rupees | Y2: Taxable Amount in text | Z2: IGST Amount in text | AA2: CGST Amount in text | AB2: SGST Amount in text | AC2: Total RCM Amount Amount in text | AD2: TOTAL NET AMOUNT
A3: 1 | B3: Hexa Climate Solutions Private Limited | C3: 45321 | D3: Registered | E3: S. S. Rana & Co. | F3: Legal fees | G3: =IF(ISBLANK(F3),0,VLOOKUP(F3,Sheet2!$U$7:$V$14,2,0)) -> 998211 | H3: Delhi | I3: 0.09 | J3: =I3 -> 0.09 | K3: 0.18 | L3: 52500 | M3: =IF($V$2=H3,0,L3*K3) -> 9450 | N3: =IF($V$2=H3,L3*I3,0) -> 0 | O3: =IF($V$2=H3,L3*I3,0) -> 0 | P3: =SUM(M3:O3) -> 9450 | Q3: =ROUND(L3,2) -> 52500 | R3: =ROUND(M3,2) -> 9450 | S3: =ROUND(N3,2) -> 0 | T3: =ROUND(O3,2) -> 0 | U3: =ROUND(P3,2) -> 9450 | W3: =SUBTOTAL(9,Q3:T3) -> 61950 | Y3: =TEXT(Q3,"#,##,###") -> 52,500 | Z3: =TEXT(R3,"#,##,###") -> 9,450 | AA3: =TEXT(S3,"#,##,###") | AB3: =TEXT(T3,"#,##,###") | AC3: =TEXT(U3,"#,##,###") -> 9,450 | AD3: =TEXT(W3,"#,##,###") -> 61,950
A4: =A3+1 -> 2 | B4: Hexa Climate Solutions Private Limited | C4: 45351 | D4: RCM/23-24/11/01 | E4: Anand Kumar Singh | F4: Legal fees | G4: =IF(ISBLANK(F4),0,VLOOKUP(F4,Sheet2!$U$7:$V$14,2,0)) -> 998211 | H4: Delhi | I4: 0.09 | J4: =I4 -> 0.09 | K4: 0.18 | L4: 15000 | M4: =IF($V$2=H4,0,L4*K4) -> 2700 | N4: =IF($V$2=H4,L4*I4,0) -> 0 | O4: =IF($V$2=H4,L4*I4,0) -> 0 | P4: =SUM(M4:O4) -> 2700 | Q4: =ROUND(L4,2) -> 15000 | R4: =ROUND(M4,2) -> 2700 | S4: =ROUND(N4,2) -> 0 | T4: =ROUND(O4,2) -> 0 | U4: =ROUND(P4,2) -> 2700 | W4: =SUBTOTAL(9,Q4:T4) -> 17700 | Y4: =TEXT(Q4,"#,##,###") -> 15,000 | Z4: =TEXT(R4,"#,##,###") -> 2,700 | AA4: =TEXT(S4,"#,##,###") | AB4: =TEXT(T4,"#,##,###") | AC4: =TEXT(U4,"#,##,###") -> 2,700 | AD4: =TEXT(W4,"#,##,###") -> 17,700
A5: =A4+1 -> 3 | B5: Hexa Climate Solutions Private Limited | C5: 45357 | D5: Registered | E5: Sarthak Advocates & Solicitors | F5: Legal fees | G5: =IF(ISBLANK(F5),0,VLOOKUP(F5,Sheet2!$U$7:$V$14,2,0)) -> 998211 | H5: Delhi | I5: 0.09 | J5: =I5 -> 0.09 | K5: 0.18 | L5: 800000 | M5: =IF($V$2=H5,0,L5*K5) -> 144000 | N5: =IF($V$2=H5,L5*I5,0) -> 0 | O5: =IF($V$2=H5,L5*I5,0) -> 0 | P5: =SUM(M5:O5) -> 144000 | Q5: =ROUND(L5,2) -> 800000 | R5: =ROUND(M5,2) -> 144000 | S5: =ROUND(N5,2) -> 0 | T5: =ROUND(O5,2) -> 0 | U5: =ROUND(P5,2) -> 144000 | W5: =SUBTOTAL(9,Q5:T5) -> 944000 | Y5: =TEXT(Q5,"#,##,###") -> 800,000 | Z5: =TEXT(R5,"#,##,###") -> 144,000 | AA5: =TEXT(S5,"#,##,###") | AB5: =TEXT(T5,"#,##,###") | AC5: =TEXT(U5,"#,##,###") -> 144,000 | AD5: =TEXT(W5,"#,##,###") -> 944,000
A6: =A5+1 -> 4 | B6: Hexa Climate Solutions Private Limited | C6: 45357 | D6: RCM/23-24/12/01 | E6: PVsyst SA | F6: Software Services | G6: =IF(ISBLANK(F6),0,VLOOKUP(F6,Sheet2!$U$7:$V$14,2,0)) -> 997331 | H6: State outside India | I6: 0.09 | J6: =I6 -> 0.09 | K6: 0.18 | L6: 57163.98 | M6: =IF($V$2=H6,0,L6*K6) -> 10289.516 | N6: =IF($V$2=H6,L6*I6,0) -> 0 | O6: =IF($V$2=H6,L6*I6,0) -> 0 | P6: =SUM(M6:O6) -> 10289.516 | Q6: =ROUND(L6,2) -> 57163.98 | R6: =ROUND(M6,2) -> 10289.52 | S6: =ROUND(N6,2) -> 0 | T6: =ROUND(O6,2) -> 0 | U6: =ROUND(P6,2) -> 10289.52 | W6: =SUBTOTAL(9,Q6:T6) -> 67453.5 | Y6: =TEXT(Q6,"#,##,###") -> 57,164 | Z6: =TEXT(R6,"#,##,###") -> 10,290 | AA6: =TEXT(S6,"#,##,###") | AB6: =TEXT(T6,"#,##,###") | AC6: =TEXT(U6,"#,##,###") -> 10,290 | AD6: =TEXT(W6,"#,##,###") -> 67,454
A7: =A6+1 -> 5 | B7: Hexa Climate Solutions Private Limited | C7: 45357 | D7: RCM/23-24/12/02 | E7: Solargis S.R.O. | F7: Software Services | G7: =IF(ISBLANK(F7),0,VLOOKUP(F7,Sheet2!$U$7:$V$14,2,0)) -> 997331 | H7: State outside India | I7: 0.09 | J7: =I7 -> 0.09 | K7: 0.18 | L7: 439764.48 | M7: =IF($V$2=H7,0,L7*K7) -> 79157.606 | N7: =IF($V$2=H7,L7*I7,0) -> 0 | O7: =IF($V$2=H7,L7*I7,0) -> 0 | P7: =SUM(M7:O7) -> 79157.606 | Q7: =ROUND(L7,2) -> 439764.48 | R7: =ROUND(M7,2) -> 79157.61 | S7: =ROUND(N7,2) -> 0 | T7: =ROUND(O7,2) -> 0 | U7: =ROUND(P7,2) -> 79157.61 | W7: =SUBTOTAL(9,Q7:T7) -> 518922.09 | Y7: =TEXT(Q7,"#,##,###") -> 439,764 | Z7: =TEXT(R7,"#,##,###") -> 79,158 | AA7: =TEXT(S7,"#,##,###") | AB7: =TEXT(T7,"#,##,###") | AC7: =TEXT(U7,"#,##,###") -> 79,158 | AD7: =TEXT(W7,"#,##,###") -> 518,922
A8: =A7+1 -> 6 | B8: Hexa Climate Solutions Private Limited | C8: 45379 | D8: RCM/23-24/12/03 | E8: EMD International A/S | F8: Software Services | G8: =IF(ISBLANK(F8),0,VLOOKUP(F8,Sheet2!$U$7:$V$14,2,0)) -> 997331 | H8: State outside India | I8: 0.09 | J8: =I8 -> 0.09 | K8: 0.18 | L8: 640795.67 | M8: =IF($V$2=H8,0,L8*K8) -> 115343.22 | N8: =IF($V$2=H8,L8*I8,0) -> 0 | O8: =IF($V$2=H8,L8*I8,0) -> 0 | P8: =SUM(M8:O8) -> 115343.22 | Q8: =ROUND(L8,2) -> 640795.67 | R8: =ROUND(M8,2) -> 115343.22 | S8: =ROUND(N8,2) -> 0 | T8: =ROUND(O8,2) -> 0 | U8: =ROUND(P8,2) -> 115343.22 | W8: =SUBTOTAL(9,Q8:T8) -> 756138.89 | Y8: =TEXT(Q8,"#,##,###") -> 640,796 | Z8: =TEXT(R8,"#,##,###") -> 115,343 | AA8: =TEXT(S8,"#,##,###") | AB8: =TEXT(T8,"#,##,###") | AC8: =TEXT(U8,"#,##,###") -> 115,343 | AD8: =TEXT(W8,"#,##,###") -> 756,139
A9: =A8+1 -> 7 | B9: Hexa Climate Solutions Private Limited | C9: 45412 | D9: Registered | E9: Shardul Amarchand Mangaldas & Co. | F9: Legal fees | G9: =IF(ISBLANK(F9),0,VLOOKUP(F9,Sheet2!$U$7:$V$14,2,0)) -> 998211 | H9: Delhi | I9: 0.09 | J9: =I9 -> 0.09 | K9: 0.18 | L9: 101600 | M9: =IF($V$2=H9,0,L9*K9) -> 18288 | N9: =IF($V$2=H9,L9*I9,0) -> 0 | O9: =IF($V$2=H9,L9*I9,0) -> 0 | P9: =SUM(M9:O9) -> 18288 | Q9: =ROUND(L9,2) -> 101600 | R9: =ROUND(M9,2) -> 18288 | S9: =ROUND(N9,2) -> 0 | T9: =ROUND(O9,2) -> 0 | U9: =ROUND(P9,2) -> 18288 | W9: =SUBTOTAL(9,Q9:T9) -> 119888 | Y9: =TEXT(Q9,"#,##,###") -> 101,600 | Z9: =TEXT(R9,"#,##,###") -> 18,288 | AA9: =TEXT(S9,"#,##,###") | AB9: =TEXT(T9,"#,##,###") | AC9: =TEXT(U9,"#,##,###") -> 18,288 | AD9: =TEXT(W9,"#,##,###") -> 119,888
A10: =A9+1 -> 8 | B10: Hexa Climate Solutions Private Limited | C10: 45419 | D10: Registered | E10: ANAND KUMAR SINGH | F10: Legal fees | G10: =IF(ISBLANK(F10),0,VLOOKUP(F10,Sheet2!$U$7:$V$14,2,0)) -> 998211 | H10: Delhi | I10: 0.09 | J10: =I10 -> 0.09 | K10: 0.18 | L10: 15000 | M10: =IF($V$2=H10,0,L10*K10) -> 2700 | N10: =IF($V$2=H10,L10*I10,0) -> 0 | O10: =IF($V$2=H10,L10*I10,0) -> 0 | P10: =SUM(M10:O10) -> 2700 | Q10: =ROUND(L10,2) -> 15000 | R10: =ROUND(M10,2) -> 2700 | S10: =ROUND(N10,2) -> 0 | T10: =ROUND(O10,2) -> 0 | U10: =ROUND(P10,2) -> 2700 | W10: =SUBTOTAL(9,Q10:T10) -> 17700 | Y10: =TEXT(Q10,"#,##,###") -> 15,000 | Z10: =TEXT(R10,"#,##,###") -> 2,700 | AA10: =TEXT(S10,"#,##,###") | AB10: =TEXT(T10,"#,##,###") | AC10: =TEXT(U10,"#,##,###") -> 2,700 | AD10: =TEXT(W10,"#,##,###") -> 17,700
A11: =A10+1 -> 9 | B11: Hexa Climate Solutions Private Limited | C11: 45442 | D11: Registered | E11: S.S. Rana & Co. | F11: Legal fees | G11: =IF(ISBLANK(F11),0,VLOOKUP(F11,Sheet2!$U$7:$V$14,2,0)) -> 998211 | H11: Delhi | I11: 0.09 | J11: =I11 -> 0.09 | K11: 0.18 | L11: 31500 | M11: =IF($V$2=H11,0,L11*K11) -> 5670 | N11: =IF($V$2=H11,L11*I11,0) -> 0 | O11: =IF($V$2=H11,L11*I11,0) -> 0 | P11: =SUM(M11:O11) -> 5670 | Q11: =ROUND(L11,2) -> 31500 | R11: =ROUND(M11,2) -> 5670 | S11: =ROUND(N11,2) -> 0 | T11: =ROUND(O11,2) -> 0 | U11: =ROUND(P11,2) -> 5670 | W11: =SUBTOTAL(9,Q11:T11) -> 37170 | Y11: =TEXT(Q11,"#,##,###") -> 31,500 | Z11: =TEXT(R11,"#,##,###") -> 5,670 | AA11: =TEXT(S11,"#,##,###") | AB11: =TEXT(T11,"#,##,###") | AC11: =TEXT(U11,"#,##,###") -> 5,670 | AD11: =TEXT(W11,"#,##,###") -> 37,170
A12: =A11+1 -> 10 | B12: Hexa Climate Solutions Private Limited | C12: 45429 | D12: RCM/24-25/02/01 | E12: Hexa Renewables India Investment PTE LTD | F12: Corporate Guarantee Fees | G12: =IF(ISBLANK(F12),0,VLOOKUP(F12,Sheet2!$U$7:$V$14,2,0)) -> 999799 | H12: State outside India | I12: 0.09 | J12: =I12 -> 0.09 | K12: 0.18 | L12: 5581770 | M12: =IF($V$2=H12,0,L12*K12) -> 1004718.6 | N12: =IF($V$2=H12,L12*I12,0) -> 0 | O12: =IF($V$2=H12,L12*I12,0) -> 0 | P12: =SUM(M12:O12) -> 1004718.6 | Q12: =ROUND(L12,2) -> 5581770 | R12: =ROUND(M12,2) -> 1004718.6 | S12: =ROUND(N12,2) -> 0 | T12: =ROUND(O12,2) -> 0 | U12: =ROUND(P12,2) -> 1004718.6 | W12: =SUBTOTAL(9,Q12:T12) -> 6586488.6 | Y12: =TEXT(Q12,"#,##,###") -> 5,581,770 | Z12: =TEXT(R12,"#,##,###") -> 1,004,719 | AA12: =TEXT(S12,"#,##,###") | AB12: =TEXT(T12,"#,##,###") | AC12: =TEXT(U12,"#,##,###") -> 1,004,719 | AD12: =TEXT(W12,"#,##,###") -> 6,586,489
A13: =A12+1 -> 11 | B13: Hexa Climate Solutions Private Limited | C13: 45504 | D13: RCM/24-25/04/01 | E13: Energy Exemplar Pty Ltd | F13: Software Services | G13: =IF(ISBLANK(F13),0,VLOOKUP(F13,Sheet2!$U$7:$V$14,2,0)) -> 997331 | H13: State outside India | I13: 0.09 | J13: =I13 -> 0.09 | K13: 0.18 | L13: 5095200 | M13: =IF($V$2=H13,0,L13*K13) -> 917136 | N13: =IF($V$2=H13,L13*I13,0) -> 0 | O13: =IF($V$2=H13,L13*I13,0) -> 0 | P13: =SUM(M13:O13) -> 917136 | Q13: =ROUND(L13,2) -> 5095200 | R13: =ROUND(M13,2) -> 917136 | S13: =ROUND(N13,2) -> 0 | T13: =ROUND(O13,2) -> 0 | U13: =ROUND(P13,2) -> 917136 | W13: =SUBTOTAL(9,Q13:T13) -> 6012336 | Y13: =TEXT(Q13,"#,##,###") -> 5,095,200 | Z13: =TEXT(R13,"#,##,###") -> 917,136 | AA13: =TEXT(S13,"#,##,###") | AB13: =TEXT(T13,"#,##,###") | AC13: =TEXT(U13,"#,##,###") -> 917,136 | AD13: =TEXT(W13,"#,##,###") -> 6,012,336
A14: =A13+1 -> 12 | B14: Hexa Climate Solutions Private Limited | C14: 45544 | D14: Registered | E14: ALLY CAR RENTAL | F14: Travelling (hired Taxi) | G14: =IF(ISBLANK(F14),0,VLOOKUP(F14,Sheet2!$U$7:$V$14,2,0)) -> 996412 | H14: Haryana | I14: 0.025 | J14: =I14 -> 0.025 | K14: 0.05 | L14: 16000 | M14: =IF($V$2=H14,0,L14*K14) -> 0 | N14: =IF($V$2=H14,L14*I14,0) -> 400 | O14: =IF($V$2=H14,L14*I14,0) -> 400 | P14: =SUM(M14:O14) -> 800 | Q14: =ROUND(L14,2) -> 16000 | R14: =ROUND(M14,2) -> 0 | S14: =ROUND(N14,2) -> 400 | T14: =ROUND(O14,2) -> 400 | U14: =ROUND(P14,2) -> 800 | W14: =SUBTOTAL(9,Q14:T14) -> 16800 | Y14: =TEXT(Q14,"#,##,###") -> 16,000 | Z14: =TEXT(R14,"#,##,###") | AA14: =TEXT(S14,"#,##,###") -> 400 | AB14: =TEXT(T14,"#,##,###") -> 400 | AC14: =TEXT(U14,"#,##,###") -> 800 | AD14: =TEXT(W14,"#,##,###") -> 16,800
A15: =A14+1 -> 13 | B15: Hexa Climate Solutions Private Limited | C15: 45544 | D15: Registered | E15: ALLY CAR RENTAL | F15: Travelling (hired Taxi) | G15: =IF(ISBLANK(F15),0,VLOOKUP(F15,Sheet2!$U$7:$V$14,2,0)) -> 996412 | H15: Haryana | I15: 0.025 | J15: =I15 -> 0.025 | K15: 0.05 | L15: 8500 | M15: =IF($V$2=H15,0,L15*K15) -> 0 | N15: =IF($V$2=H15,L15*I15,0) -> 212.5 | O15: =IF($V$2=H15,L15*I15,0) -> 212.5 | P15: =SUM(M15:O15) -> 425 | Q15: =ROUND(L15,2) -> 8500 | R15: =ROUND(M15,2) -> 0 | S15: =ROUND(N15,2) -> 212.5 | T15: =ROUND(O15,2) -> 212.5 | U15: =ROUND(P15,2) -> 425 | W15: =SUBTOTAL(9,Q15:T15) -> 8925 | Y15: =TEXT(Q15,"#,##,###") -> 8,500 | Z15: =TEXT(R15,"#,##,###") | AA15: =TEXT(S15,"#,##,###") -> 213 | AB15: =TEXT(T15,"#,##,###") -> 213 | AC15: =TEXT(U15,"#,##,###") -> 425 | AD15: =TEXT(W15,"#,##,###") -> 8,925
... A24: =A23+1 -> 22 | B24: Hexa Climate Solutions Private Limited | C24: 45565 | D24: Registered | E24: Shardul Amarchand Mangaldas & Co. | F24: Legal fees | G24: =IF(ISBLANK(F24),0,VLOOKUP(F24,Sheet2!$U$7:$V$14,2,0)) -> 998211 | H24: Delhi | I24: 0.09 | J24: =I24 -> 0.09 | K24: 0.18 | L24: 413875 | M24: =IF($V$2=H24,0,L24*K24) -> 74497.5 | N24: =IF($V$2=H24,L24*I24,0) -> 0 | O24: =IF($V$2=H24,L24*I24,0) -> 0 | P24: =SUM(M24:O24) -> 74497.5 | Q24: =ROUND(L24,2) -> 413875 | R24: =ROUND(M24,2) -> 74497.5 | S24: =ROUND(N24,2) -> 0 | T24: =ROUND(O24,2) -> 0 | U24: =ROUND(P24,2) -> 74497.5 | W24: =SUBTOTAL(9,Q24:T24) -> 488372.5 | Y24: =TEXT(Q24,"#,##,###") -> 413,875 | Z24: =TEXT(R24,"#,##,###") -> 74,498 | AA24: =TEXT(S24,"#,##,###") | AB24: =TEXT(T24,"#,##,###") | AC24: =TEXT(U24,"#,##,###") -> 74,498 | AD24: =TEXT(W24,"#,##,###") -> 488,373
A25: =A24+1 -> 23 | B25: Hexa Climate Solutions Private Limited | C25: 45565 | D25: Registered | E25: Shardul Amarchand Mangaldas & Co. | F25: Legal fees | G25: =IF(ISBLANK(F25),0,VLOOKUP(F25,Sheet2!$U$7:$V$14,2,0)) -> 998211 | H25: Delhi | I25: 0.09 | J25: =I25 -> 0.09 | K25: 0.18 | L25: 400000 | M25: =IF($V$2=H25,0,L25*K25) -> 72000 | N25: =IF($V$2=H25,L25*I25,0) -> 0 | O25: =IF($V$2=H25,L25*I25,0) -> 0 | P25: =SUM(M25:O25) -> 72000 | Q25: =ROUND(L25,2) -> 400000 | R25: =ROUND(M25,2)+1 -> 72001 | S25: =ROUND(N25,2) -> 0 | T25: =ROUND(O25,2) -> 0 | U25: =ROUND(P25,2) -> 72000 | W25: =SUBTOTAL(9,Q25:T25) -> 472001 | Y25: =TEXT(Q25,"#,##,###") -> 400,000 | Z25: =TEXT(R25,"#,##,###") -> 72,001 | AA25: =TEXT(S25,"#,##,###") | AB25: =TEXT(T25,"#,##,###") | AC25: =TEXT(U25,"#,##,###") -> 72,000 | AD25: =TEXT(W25,"#,##,###") -> 472,001
A26: =A25+1 -> 24 | B26: Hexa Climate Solutions Private Limited | C26: 45565 | D26: Registered | E26: Shardul Amarchand Mangaldas & Co. | F26: Legal fees | G26: =IF(ISBLANK(F26),0,VLOOKUP(F26,Sheet2!$U$7:$V$14,2,0)) -> 998211 | H26: Delhi | I26: 0.09 | J26: =I26 -> 0.09 | K26: 0.18 | L26: 585500 | M26: =IF($V$2=H26,0,L26*K26) -> 105390 | N26: =IF($V$2=H26,L26*I26,0) -> 0 | O26: =IF($V$2=H26,L26*I26,0) -> 0 | P26: =SUM(M26:O26) -> 105390 | Q26: =ROUND(L26,2) -> 585500 | R26: =ROUND(M26,2) -> 105390 | S26: =ROUND(N26,2) -> 0 | T26: =ROUND(O26,2) -> 0 | U26: =ROUND(P26,2) -> 105390 | W26: =SUBTOTAL(9,Q26:T26) -> 690890 | Y26: =TEXT(Q26,"#,##,###") -> 585,500 | Z26: =TEXT(R26,"#,##,###") -> 105,390 | AA26: =TEXT(S26,"#,##,###") | AB26: =TEXT(T26,"#,##,###") | AC26: =TEXT(U26,"#,##,###") -> 105,390 | AD26: =TEXT(W26,"#,##,###") -> 690,890
A27: =A26+1 -> 25 | B27: Hexa Climate Solutions Private Limited | C27: 45565 | D27: Registered | E27: Shardul Amarchand Mangaldas & Co. | F27: Legal fees | G27: =IF(ISBLANK(F27),0,VLOOKUP(F27,Sheet2!$U$7:$V$14,2,0)) -> 998211 | H27: Delhi | I27: 0.09 | J27: =I27 -> 0.09 | K27: 0.18 | L27: 375000 | M27: =IF($V$2=H27,0,L27*K27) -> 67500 | N27: =IF($V$2=H27,L27*I27,0) -> 0 | O27: =IF($V$2=H27,L27*I27,0) -> 0 | P27: =SUM(M27:O27) -> 67500 | Q27: =ROUND(L27,2) -> 375000 | R27: =ROUND(M27,2) -> 67500 | S27: =ROUND(N27,2) -> 0 | T27: =ROUND(O27,2) -> 0 | U27: =ROUND(P27,2) -> 67500 | W27: =SUBTOTAL(9,Q27:T27) -> 442500 | Y27: =TEXT(Q27,"#,##,###") -> 375,000 | Z27: =TEXT(R27,"#,##,###") -> 67,500 | AA27: =TEXT(S27,"#,##,###") | AB27: =TEXT(T27,"#,##,###") | AC27: =TEXT(U27,"#,##,###") -> 67,500 | AD27: =TEXT(W27,"#,##,###") -> 442,500
A28: =A27+1 -> 26 | B28: Hexa Climate Solutions Private Limited | C28: 45565 | D28: Registered | E28: Shardul Amarchand Mangaldas & Co. | F28: Legal fees | G28: =IF(ISBLANK(F28),0,VLOOKUP(F28,Sheet2!$U$7:$V$14,2,0)) -> 998211 | H28: Delhi | I28: 0.09 | J28: =I28 -> 0.09 | K28: 0.18 | L28: 116750 | M28: =IF($V$2=H28,0,L28*K28) -> 21015 | N28: =IF($V$2=H28,L28*I28,0) -> 0 | O28: =IF($V$2=H28,L28*I28,0) -> 0 | P28: =SUM(M28:O28) -> 21015 | Q28: =ROUND(L28,2) -> 116750 | R28: =ROUND(M28,2) -> 21015 | S28: =ROUND(N28,2) -> 0 | T28: =ROUND(O28,2) -> 0 | U28: =ROUND(P28,2) -> 21015 | W28: =SUBTOTAL(9,Q28:T28) -> 137765 | Y28: =TEXT(Q28,"#,##,###") -> 116,750 | Z28: =TEXT(R28,"#,##,###") -> 21,015 | AA28: =TEXT(S28,"#,##,###") | AB28: =TEXT(T28,"#,##,###") | AC28: =TEXT(U28,"#,##,###") -> 21,015 | AD28: =TEXT(W28,"#,##,###") -> 137,765
A29: =A28+1 -> 27 | B29: Hexa Climate Solutions Private Limited | C29: 45565 | D29: Registered | E29: Shardul Amarchand Mangaldas & Co. | F29: Legal fees | G29: =IF(ISBLANK(F29),0,VLOOKUP(F29,Sheet2!$U$7:$V$14,2,0)) -> 998211 | H29: Delhi | I29: 0.09 | J29: =I29 -> 0.09 | K29: 0.18 | L29: 400000 | M29: =IF($V$2=H29,0,L29*K29) -> 72000 | N29: =IF($V$2=H29,L29*I29,0) -> 0 | O29: =IF($V$2=H29,L29*I29,0) -> 0 | P29: =SUM(M29:O29) -> 72000 | Q29: =ROUND(L29,2) -> 400000 | R29: =ROUND(M29,2) -> 72000 | S29: =ROUND(N29,2) -> 0 | T29: =ROUND(O29,2) -> 0 | U29: =ROUND(P29,2) -> 72000 | W29: =SUBTOTAL(9,Q29:T29) -> 472000 | Y29: =TEXT(Q29,"#,##,###") -> 400,000 | Z29: =TEXT(R29,"#,##,###") -> 72,000 | AA29: =TEXT(S29,"#,##,###") | AB29: =TEXT(T29,"#,##,###") | AC29: =TEXT(U29,"#,##,###") -> 72,000 | AD29: =TEXT(W29,"#,##,###") -> 472,000
A30: =A29+1 -> 28 | B30: Hexa Climate Solutions Private Limited | C30: 45565 | D30: Registered | E30: Shardul Amarchand Mangaldas & Co. | F30: Legal fees | G30: =IF(ISBLANK(F30),0,VLOOKUP(F30,Sheet2!$U$7:$V$14,2,0)) -> 998211 | H30: Delhi | I30: 0.09 | J30: =I30 -> 0.09 | K30: 0.18 | L30: 500000 | M30: =IF($V$2=H30,0,L30*K30) -> 90000 | N30: =IF($V$2=H30,L30*I30,0) -> 0 | O30: =IF($V$2=H30,L30*I30,0) -> 0 | P30: =SUM(M30:O30) -> 90000 | Q30: =ROUND(L30,2) -> 500000 | R30: =ROUND(M30,2) -> 90000 | S30: =ROUND(N30,2) -> 0 | T30: =ROUND(O30,2) -> 0 | U30: =ROUND(P30,2) -> 90000 | W30: =SUBTOTAL(9,Q30:T30) -> 590000 | Y30: =TEXT(Q30,"#,##,###") -> 500,000 | Z30: =TEXT(R30,"#,##,###") -> 90,000 | AA30: =TEXT(S30,"#,##,###") | AB30: =TEXT(T30,"#,##,###") | AC30: =TEXT(U30,"#,##,###") -> 90,000 | AD30: =TEXT(W30,"#,##,###") -> 590,000
A31: =A30+1 -> 29 | B31: Hea Renewable Solutions Private Limited | C31: 45492 | D31: RCM/24-25/04/01 | E31: Mohit Gupta Advocate | F31: Legal fees | G31: =IF(ISBLANK(F31),0,VLOOKUP(F31,Sheet2!$U$7:$V$14,2,0)) -> 998211 | H31: Haryana | I31: 0.09 | J31: =I31 -> 0.09 | K31: 0.18 | L31: 70125 | M31: =IF($V$2=H31,0,L31*K31) -> 0 | N31: =IF($V$2=H31,L31*I31,0) -> 6311.25 | O31: =IF($V$2=H31,L31*I31,0) -> 6311.25 | P31: =SUM(M31:O31) -> 12622.5 | Q31: =ROUND(L31,2) -> 70125 | R31: =ROUND(M31,2) -> 0 | S31: =ROUND(N31,2) -> 6311.25 | T31: =ROUND(O31,2) -> 6311.25 | U31: =ROUND(P31,2) -> 12622.5 | W31: =SUBTOTAL(9,Q31:T31) -> 82747.5 | Y31: =TEXT(Q31,"#,##,###") -> 70,125 | Z31: =TEXT(R31,"#,##,###") | AA31: =TEXT(S31,"#,##,###") -> 6,311 | AB31: =TEXT(T31,"#,##,###") -> 6,311 | AC31: =TEXT(U31,"#,##,###") -> 12,623 | AD31: =TEXT(W31,"#,##,###") -> 82,748
L34: 140000
L36: =L22-L34 -> 1260000

Sheet Sheet2
A4: Company Name | B4: GST Number | C4: Pan Number | D4: Address | N4: State Code | O4: States Name | P4: 27
A5: REL Kumbhari Solar Project 1 Private Limited | B5: 27AAMCR1113N1Z6 | C5: AAMCR1113N | D5: BC 105 havlock road belgaum | N5: 1 | O5: Jammu And Kashmir | P5: =VLOOKUP(P4,N5:O40,2,0) -> Maharashtra
A6: REL Kumbhari Solar Project 2 Private Limited | B6: 27AAMCR1217P1ZX | C6: AAMCR1217P | N6: 2 | O6: Himachal Pradesh | U6: List of services | V6: SAC code
A7: REL Kumbhari Solar Project 3 Private Limited | B7: 27AAMCR1585J1ZU | C7: AAMCR1585J | N7: 3 | O7: Punjab | U7: GTA Services | V7: 996791
A8: REL Kumbhari Solar Project 4 Private Limited | B8: 27AAMCR3051K1Z3 | C8: AAMCR3051K | N8: 4 | O8: Chandigarh | U8: Legal fees | V8: 998211
A9: REL Kumbhari Solar Project 5 Private Limited | B9: 27AAMCR3052L1Z0 | C9: AAMCR3052L | N9: 5 | O9: Uttarakhand | U9: Travelling (hired Taxi) | V9: 996412
A10: REL Kumbhari Solar Project 6 Private Limited | B10: 27AAMCR9750P1ZB | C10: AAMCR9750P | N10: 6 | O10: Haryana | U10: Director fees | V10: 998311
A11: REL Kumbhari Solar Project 7 Private Limited | B11: 27AANCR2134A1ZP | C11: AANCR2134A | N11: 7 | O11: Delhi | U11: Security services | V11: 998529
A12: REL Kumbhari Solar Project 8 Private Limited | B12: 27AANCR2140L1Z4 | C12: AANCR2140L | N12: 8 | O12: Rajasthan | U12: Guest house rent | V12: 996311
A13: REL Kumbhari Solar Project 9 Private Limited | B13: 27AANCR2871A1ZD | C13: AANCR2871A | N13: 9 | O13: Uttar Pradesh | U13: Software Services | V13: 997331
A14: REL Kumbhari Solar Project 10 Private Limited | B14: 27AANCR3067Q1ZI | C14: AANCR3067Q | N14: 10 | O14: Bihar | U14: Corporate Guarantee Fees | V14: 999799
A15: REL WARDHA SOLAR PROJECT 1 PRIVATE LIMITED | B15: 27AANCR3134L1Z0 | C15: AANCR3134L | N15: 11 | O15: Sikkim
A16: REL WARDHA SOLAR PROJECT 2 PRIVATE LIMITED | B16: 27AANCR3248P1ZL | C16: AANCR3248P | N16: 12 | O16: Arunachal Pradesh
A17: REL WARDHA SOLAR PROJECT 3 PRIVATE LIMITED | B17: 27AANCR3247C1ZD | C17: AANCR3247C | N17: 13 | O17: Nagaland
A18: REL WARDHA SOLAR PROJECT 4 PRIVATE LIMITED | B18: 27AANCR4018F1ZC | C18: AANCR4018F | N18: 14 | O18: Manipur
A19: REL WARDHA SOLAR PROJECT 5 PRIVATE LIMITED | B19: 27AANCR4055L1ZU | C19: AANCR4055L | N19: 15 | O19: Mizoram
A20: RAVINDRA ENERGY MHSP LLP | B20: 27ABEFR6216N1ZS | C20: ABEFR6216N | N20: 16 | O20: Tripura
N21: 17 | O21: Meghalaya
N22: 18 | O22: Assam
N23: 19 | O23: West Bengal
N24: 20 | O24: Jharkhand
N25: 21 | O25: Orissa
N26: 22 | O26: Chhattisgarh
N27: 23 | O27: Madhya Pradesh
N28: 24 | O28: Gujarat
N29: 26 | O29: Dadar and Nagar Haveli & Daman and Diu
N30: 27 | O30: Maharashtra
N31: 29 | O31: Karnataka
N32: 30 | O32: Goa
... N40: 38 | O40: Ladakh

Sheet Sheet3
A1: Company Name | B1: Inv date | C1: Inv no | D1: Party Name | E1: Type of Service | F1: SAC CODE | G1: Party state | H1: CGST % | I1: SGST % | J1: IGST % | K1: Taxable Amount in text | L1: IGST Amount in text | M1: CGST Amount in text | N1: SGST Amount in text | O1: Total RCM Amount Amount in text | P1: TOTAL NET AMOUNT
A2: RAVINDRA ENERGY MHSP LLP | B2: 44651 | C2: RCM/21-22/1 | D2: Rajshekhar B Kore(Advocate) | E2: Legal fees | F2: 998211 | G2: Maharashtra | H2: 0.09 | I2: 0.09 | J2: 0.18 | K2: 11,600 | M2: 1,044 | N2: 1,044 | O2: 2,088 | P2: 13,688
A3: RAVINDRA ENERGY MHSP LLP | B3: 44658 | C3: RCM/22-23/1 | D3: Abhay Nevagi & Associates | E3: Legal fees | F3: 998211 | G3: Maharashtra | H3: 0.09 | I3: 0.09 | J3: 0.18 | K3: 2,80,000 | M3: 25,200 | N3: 25,200 | O3: 50,400 | P3: 3,30,400
A4: RAVINDRA ENERGY MHSP LLP | B4: 44658 | C4: RCM/22-23/2 | D4: Abhay Nevagi & Associates | E4: Legal fees | F4: 998211 | G4: Maharashtra | H4: 0.09 | I4: 0.09 | J4: 0.18 | K4: 1,70,000 | M4: 15,300 | N4: 15,300 | O4: 30,600 | P4: 2,00,600
A5: RAVINDRA ENERGY MHSP LLP | B5: 44659 | C5: RCM/22-23/3 | D5: Rajshekhar B Kore(Advocate) | E5: Legal fees | F5: 998211 | G5: Maharashtra | H5: 0.09 | I5: 0.09 | J5: 0.18 | K5: 1,00,000 | M5: 9,000 | N5: 9,000 | O5: 18,000 | P5: 1,18,000
A6: RAVINDRA ENERGY MHSP LLP | B6: 44678 | C6: RCM/22-23/4 | D6: Abhay Nevagi & Associates | E6: Legal fees | F6: 998211 | G6: Maharashtra | H6: 0.09 | I6: 0.09 | J6: 0.18 | K6: 1,60,000 | M6: 14,400 | N6: 14,400 | O6: 28,800 | P6: 1,88,800
A7: RAVINDRA ENERGY MHSP LLP | B7: 44741 | C7: RCM/22-23/5 | D7: Abhay Nevagi & Associates | E7: Legal fees | F7: 998211 | G7: Maharashtra | H7: 0.09 | I7: 0.09 | J7: 0.18 | K7: 60,000 | M7: 5,400 | N7: 5,400 | O7: 10,800 | P7: 70,800
A8: RAVINDRA ENERGY MHSP LLP | B8: 44741 | C8: RCM/22-23/6 | D8: Abhay Nevagi & Associates | E8: Legal fees | F8: 998211 | G8: Maharashtra | H8: 0.09 | I8: 0.09 | J8: 0.18 | K8: 2,40,000 | M8: 21,600 | N8: 21,600 | O8: 43,200 | P8: 2,83,200
A9: RAVINDRA ENERGY MHSP LLP | B9: 44741 | C9: RCM/22-23/7 | D9: Abhay Nevagi & Associates | E9: Legal fees | F9: 998211 | G9: Maharashtra | H9: 0.09 | I9: 0.09 | J9: 0.18 | K9: 2,10,000 | M9: 18,900 | N9: 18,900 | O9: 37,800 | P9: 2,47,800
A10: RAVINDRA ENERGY MHSP LLP | B10: 44659 | C10: RCM/22-23/8 | D10: Rajshekhar B Kore(Advocate) | E10: Legal fees | F10: 998211 | G10: Maharashtra | H10: 0.09 | I10: 0.09 | J10: 0.18 | K10: 75,000 | M10: 6,750 | N10: 6,750 | O10: 13,500 | P10: 88,500
A11: RAVINDRA ENERGY MHSP LLP | B11: 44773 | C11: RCM/22-23/9 | D11: Salim Hussain Bagwan | E11: Guest House Rent | F11: 996311 | G11: Maharashtra | H11: 0.09 | I11: 0.09 | J11: 0.18 | K11: 6,000 | M11: 540 | N11: 540 | O11: 1,080 | P11: 7,080
A12: RAVINDRA ENERGY MHSP LLP | B12: 44804 | C12: RCM/22-23/10 | D12: Salim Hussain Bagwan | E12: Guest House Rent | F12: 996311 | G12: Maharashtra | H12: 0.09 | I12: 0.09 | J12: 0.18 | K12: 6,000 | M12: 540 | N12: 540 | O12: 1,080 | P12: 7,080
A13: RAVINDRA ENERGY MHSP LLP | B13: 44833 | C13: RCM/22-23/11 | D13: RAJE CRANE SERVICE | E13: GTA Services | F13: 996791 | G13: Maharashtra | H13: 0.025 | I13: 0.025 | J13: 0.05 | K13: 4,000 | M13: 100 | N13: 100 | O13: 200 | P13: 4,200
... A15: RAVINDRA ENERGY MHSP LLP | B15: 44833 | C15: RCM/22-23/13 | D15: Salim Hussain Bagwan | E15: Guest House Rent | F15: 996311 | G15: Maharashtra | H15: 0.09 | I15: 0.09 | J15: 0.18 | K15: 7,000 | M15: 630 | N15: 630 | O15: 1,260 | P15: 8,260
A16: RAVINDRA ENERGY MHSP LLP | B16: 44833 | C16: RCM/22-23-14 | D16: VRL LOGISTICS LTD | E16: GTA Services | F16: 996791 | G16: Karnataka | H16: 0.025 | I16: 0.025 | J16: 0.05 | K16: 980 | L16: 49 | O16: 49 | P16: 1,029
A17: RAVINDRA ENERGY MHSP LLP | B17: 44865 | C17: RCM/22-23/15 | D17: Abhay Nevagi & Associates | E17: Legal fees | F17: 998211 | G17: Maharashtra | H17: 0.09 | I17: 0.09 | J17: 0.18 | K17: 1,20,000 | M17: 10,800 | N17: 10,800 | O17: 21,600 | P17: 1,41,600
A18: RAVINDRA ENERGY MHSP LLP | B18: 44865 | C18: RCM/22-23/16 | D18: Salim Hussain Bagwan | E18: Guest House Rent | F18: 996311 | G18: Maharashtra | H18: 0.09 | I18: 0.09 | J18: 0.18 | K18: 6,000 | M18: 540 | N18: 540 | O18: 1,080 | P18: 7,080
A19: RAVINDRA ENERGY MHSP LLP | B19: 44895 | C19: RCM/22-23/17 | D19: Salim Hussain Bagwan | E19: Guest House Rent | F19: 996311 | G19: Maharashtra | H19: 0.09 | I19: 0.09 | J19: 0.18 | K19: 7,000 | M19: 630 | N19: 630 | O19: 1,260 | P19: 8,260
A20: RAVINDRA ENERGY MHSP LLP | B20: 44925 | C20: RCM/22-23/18 | D20: Salim Hussain Bagwan | E20: Guest House Rent | F20: 996311 | G20: Maharashtra | H20: 0.09 | I20: 0.09 | J20: 0.18 | K20: 7,000 | M20: 630 | N20: 630 | O20: 1,260 | P20: 8,260
A21: RAVINDRA ENERGY MHSP LLP | B21: 44925 | C21: RCM/22-23/19 | D21: Rajshekhar B Kore(Advocate) | E21: Legal fees | F21: 998211 | G21: Maharashtra | H21: 0.09 | I21: 0.09 | J21: 0.18 | K21: 45,000 | M21: 4,050 | N21: 4,050 | O21: 8,100 | P21: 53,100
A22: RAVINDRA ENERGY MHSP LLP | B22: 44985 | C22: RCM/22-23/20 | D22: VRL LOGISTICS LTD | E22: GTA Services | F22: 996791 | G22: Maharashtra | H22: 0.025 | I22: 0.025 | J22: 0.05 | K22: 846 | M22: 21 | N22: 21 | O22: 42 | P22: 888
A23: RAVINDRA ENERGY MHSP LLP | B23: 44985 | C23: RCM/22-23/21 | D23: VRL LOGISTICS LTD | E23: GTA Services | F23: 996791 | G23: Karnataka | H23: 0.025 | I23: 0.025 | J23: 0.05 | K23: 854 | L23: 43 | O23: 43 | P23: 897
A24: RAVINDRA ENERGY MHSP LLP | B24: 44985 | C24: RCM/22-23/22 | D24: VRL LOGISTICS LTD | E24: GTA Services | F24: 996791 | G24: Maharashtra | H24: 0.025 | I24: 0.025 | J24: 0.05 | K24: 310 | M24: 8 | N24: 8 | O24: 16 | P24: 326
A25: RAVINDRA ENERGY MHSP LLP | B25: 44985 | C25: RCM/22-23/23 | D25: VRL LOGISTICS LTD | E25: GTA Services | F25: 996791 | G25: Karnataka | H25: 0.025 | I25: 0.025 | J25: 0.05 | K25: 594 | L25: 31 | O25: 30 | P25: 625
A26: RAVINDRA ENERGY MHSP LLP | B26: 44985 | C26: RCM/22-23/24 | D26: VRL LOGISTICS LTD | E26: GTA Services | F26: 996791 | G26: Maharashtra | H26: 0.025 | I26: 0.025 | J26: 0.05 | K26: 266 | M26: 7 | N26: 7 | O26: 13 | P26: 279
A27: RAVINDRA ENERGY MHSP LLP | B27: 44985 | C27: RCM/22-23/25 | D27: VRL LOGISTICS LTD | E27: GTA Services | F27: 996791 | G27: Karnataka | H27: 0.025 | I27: 0.025 | J27: 0.05 | K27: 720 | L27: 36 | O27: 36 | P27: 756
A28: RAVINDRA ENERGY MHSP LLP | B28: 44985 | C28: RCM/22-23/26 | D28: TCI EXPRESS | E28: GTA Services | F28: 996791 | G28: Karnataka | H28: 0.025 | I28: 0.025 | J28: 0.05 | K28: 300 | L28: 15 | O28: 15 | P28: 315
A29: RAVINDRA ENERGY MHSP LLP | B29: 44985 | C29: RCM/22-23/27 | D29: Pravin s Patil | E29: Travelling (hired Taxi) | F29: 996412 | G29: Maharashtra | H29: 0.025 | I29: 0.025 | J29: 0.05 | K29: 5,000 | M29: 125 | N29: 125 | O29: 250 | P29: 5,250
A30: RAVINDRA ENERGY MHSP LLP | B30: 45016 | C30: RCM/22-23/28 | D30: Abhay Nevagi & Associates | E30: Legal fees | F30: 998211 | G30: Karnataka | H30: 0.09 | I30: 0.09 | J30: 0.18 | K30: 90,000 | L30: 16,200 | O30: 16,200 | P30: 1,06,200
A31: RAVINDRA ENERGY MHSP LLP | B31: 44985 | C31: RCM/22-23/29 | D31: VRL LOGISTICS LTD | E31: GTA Services | F31: 996791 | G31: Karnataka | H31: 0.025 | I31: 0.025 | J31: 0.05 | K31: 999 | L31: 50 | O31: 50 | P31: 1,049
A32: RAVINDRA ENERGY MHSP LLP | B32: 44985 | C32: RCM/22-23/30 | D32: VRL LOGISTICS LTD | E32: GTA Services | F32: 996791 | G32: Maharashtra | H32: 0.025 | I32: 0.025 | J32: 0.05 | K32: 250 | M32: 6 | N32: 6 | O32: 13 | P32: 263
A33: RAVINDRA ENERGY MHSP LLP | B33: 44985 | C33: RCM/22-23/31 | D33: VRL LOGISTICS LTD | E33: GTA Services | F33: 996791 | G33: Karnataka | H33: 0.025 | I33: 0.025 | J33: 0.05 | K33: 800 | L33: 40 | O33: 40 | P33: 840
A34: RAVINDRA ENERGY MHSP LLP | B34: 45046 | C34: RCM/23-24/1 | D34: M.A Shaik | E34: Legal fees | F34: 998211 | G34: Maharashtra | H34: 0.09 | I34: 0.09 | J34: 0.18 | K34: 5,000 | M34: 450 | N34: 450 | O34: 900 | P34: 5,900
A35: RAVINDRA ENERGY MHSP LLP | B35: 45046 | C35: RCM/23-24/2 | D35: Vinayak N Deshpande | E35: Legal fees | F35: 998211 | G35: Maharashtra | H35: 0.09 | I35: 0.09 | J35: 0.18 | K35: 2,000 | M35: 180 | N35: 180 | O35: 360 | P35: 2,360
A36: RAVINDRA ENERGY MHSP LLP | B36: 45046 | C36: RCM/23-24/3 | D36: Vinayak N Deshpande | E36: Legal fees | F36: 998211 | G36: Maharashtra | H36: 0.09 | I36: 0.09 | J36: 0.18 | K36: 6,000 | M36: 540 | N36: 540 | O36: 1,080 | P36: 7,080
A37: RAVINDRA ENERGY MHSP LLP | B37: 45046 | C37: RCM/23-24/4 | D37: Vinayak N Deshpande | E37: Legal fees | F37: 998211 | G37: Maharashtra | H37: 0.09 | I37: 0.09 | J37: 0.18 | K37: 9,500 | M37: 855 | N37: 855 | O37: 1,710 | P37: 11,210
A38: RAVINDRA ENERGY MHSP LLP | B38: 45046 | C38: RCM/23-24/5 | D38: VRL LOGISTICS LTD | E38: GTA Services | F38: 996791 | G38: Karnataka | H38: 0.025 | I38: 0.025 | J38: 0.05 | K38: 1,376 | L38: 69 | O38: 69 | P38: 1,445
A39: RAVINDRA ENERGY MHSP LLP | B39: 45046 | C39: RCM/23-24/6 | D39: SOLAPUR GOODS TRANSPORT | E39: GTA Services | F39: 996791 | G39: Maharashtra | H39: 0.025 | I39: 0.025 | J39: 0.05 | K39: 160 | M39: 4 | N39: 4 | O39: 8 | P39: 168
A40: RAVINDRA ENERGY MHSP LLP | B40: 45046 | C40: RCM/23-24/7 | D40: VRL LOGISTICS LTD | E40: GTA Services | F40: 996791 | G40: Maharashtra | H40: 0.025 | I40: 0.025 | J40: 0.05 | K40: 2,670 | M40: 67 | N40: 67 | O40: 134 | P40: 2,804
A41: RAVINDRA ENERGY MHSP LLP | B41: 45046 | C41: RCM/23-24/8 | D41: TCI EXPRESS | E41: GTA Services | F41: 996791 | G41: Karnataka | H41: 0.025 | I41: 0.025 | J41: 0.05 | K41: 950 | L41: 48 | O41: 48 | P41: 998
...
